2025-08-07 20:21:24,290 ERROR: Exception on /dashboard [GET] [in /home/runner/workspace/.pythonlibs/lib/python3.11/site-packages/flask/app.py:875]
Traceback (most recent call last):
  File "/home/runner/workspace/.pythonlibs/lib/python3.11/site-packages/sqlalchemy/engine/base.py", line 1963, in _exec_single_context
    self.dialect.do_execute(
  File "/home/runner/workspace/.pythonlibs/lib/python3.11/site-packages/sqlalchemy/engine/default.py", line 943, in do_execute
    cursor.execute(statement, parameters)
psycopg2.errors.UndefinedColumn: column users.active does not exist
LINE 1: ...sers_phone, users.created_at AS users_created_at, users.acti...
                                                             ^
HINT:  Perhaps you meant to reference the column "users.is_active".


The above exception was the direct cause of the following exception:

Traceback (most recent call last):
  File "/home/runner/workspace/.pythonlibs/lib/python3.11/site-packages/flask/app.py", line 1511, in wsgi_app
    response = self.full_dispatch_request()
               ^^^^^^^^^^^^^^^^^^^^^^^^^^^^
  File "/home/runner/workspace/.pythonlibs/lib/python3.11/site-packages/flask/app.py", line 919, in full_dispatch_request
    rv = self.handle_user_exception(e)
         ^^^^^^^^^^^^^^^^^^^^^^^^^^^^^
  File "/home/runner/workspace/.pythonlibs/lib/python3.11/site-packages/flask/app.py", line 917, in full_dispatch_request
    rv = self.dispatch_request()
         ^^^^^^^^^^^^^^^^^^^^^^^
  File "/home/runner/workspace/.pythonlibs/lib/python3.11/site-packages/flask/app.py", line 902, in dispatch_request
    return self.ensure_sync(self.view_functions[rule.endpoint])(**view_args)  # type: ignore[no-any-return]
           ^^^^^^^^^^^^^^^^^^^^^^^^^^^^^^^^^^^^^^^^^^^^^^^^^^^^^^^^^^^^^^^^^
  File "/home/runner/workspace/.pythonlibs/lib/python3.11/site-packages/flask_login/utils.py", line 284, in decorated_view
    elif not current_user.is_authenticated:
             ^^^^^^^^^^^^^^^^^^^^^^^^^^^^^
  File "/home/runner/workspace/.pythonlibs/lib/python3.11/site-packages/werkzeug/local.py", line 318, in __get__
    obj = instance._get_current_object()
          ^^^^^^^^^^^^^^^^^^^^^^^^^^^^^^
  File "/home/runner/workspace/.pythonlibs/lib/python3.11/site-packages/werkzeug/local.py", line 526, in _get_current_object
    return get_name(local())
                    ^^^^^^^
  File "/home/runner/workspace/.pythonlibs/lib/python3.11/site-packages/flask_login/utils.py", line 25, in <lambda>
    current_user = LocalProxy(lambda: _get_user())
                                      ^^^^^^^^^^^
  File "/home/runner/workspace/.pythonlibs/lib/python3.11/site-packages/flask_login/utils.py", line 370, in _get_user
    current_app.login_manager._load_user()
  File "/home/runner/workspace/.pythonlibs/lib/python3.11/site-packages/flask_login/login_manager.py", line 364, in _load_user
    user = self._user_callback(user_id)
           ^^^^^^^^^^^^^^^^^^^^^^^^^^^^
  File "/home/runner/workspace/app.py", line 51, in load_user
    return User.query.get(int(user_id))
           ^^^^^^^^^^^^^^^^^^^^^^^^^^^^
  File "<string>", line 2, in get
  File "/home/runner/workspace/.pythonlibs/lib/python3.11/site-packages/sqlalchemy/util/deprecations.py", line 386, in warned
    return fn(*args, **kwargs)  # type: ignore[no-any-return]
           ^^^^^^^^^^^^^^^^^^^
  File "/home/runner/workspace/.pythonlibs/lib/python3.11/site-packages/sqlalchemy/orm/query.py", line 1126, in get
    return self._get_impl(ident, loading.load_on_pk_identity)
           ^^^^^^^^^^^^^^^^^^^^^^^^^^^^^^^^^^^^^^^^^^^^^^^^^^
  File "/home/runner/workspace/.pythonlibs/lib/python3.11/site-packages/sqlalchemy/orm/query.py", line 1135, in _get_impl
    return self.session._get_impl(
           ^^^^^^^^^^^^^^^^^^^^^^^
  File "/home/runner/workspace/.pythonlibs/lib/python3.11/site-packages/sqlalchemy/orm/session.py", line 3873, in _get_impl
    return db_load_fn(
           ^^^^^^^^^^^
  File "/home/runner/workspace/.pythonlibs/lib/python3.11/site-packages/sqlalchemy/orm/loading.py", line 694, in load_on_pk_identity
    session.execute(
  File "/home/runner/workspace/.pythonlibs/lib/python3.11/site-packages/sqlalchemy/orm/session.py", line 2365, in execute
    return self._execute_internal(
           ^^^^^^^^^^^^^^^^^^^^^^^
  File "/home/runner/workspace/.pythonlibs/lib/python3.11/site-packages/sqlalchemy/orm/session.py", line 2251, in _execute_internal
    result: Result[Any] = compile_state_cls.orm_execute_statement(
                          ^^^^^^^^^^^^^^^^^^^^^^^^^^^^^^^^^^^^^^^^
  File "/home/runner/workspace/.pythonlibs/lib/python3.11/site-packages/sqlalchemy/orm/context.py", line 306, in orm_execute_statement
    result = conn.execute(
             ^^^^^^^^^^^^^
  File "/home/runner/workspace/.pythonlibs/lib/python3.11/site-packages/sqlalchemy/engine/base.py", line 1415, in execute
    return meth(
           ^^^^^
  File "/home/runner/workspace/.pythonlibs/lib/python3.11/site-packages/sqlalchemy/sql/elements.py", line 523, in _execute_on_connection
    return connection._execute_clauseelement(
           ^^^^^^^^^^^^^^^^^^^^^^^^^^^^^^^^^^
  File "/home/runner/workspace/.pythonlibs/lib/python3.11/site-packages/sqlalchemy/engine/base.py", line 1637, in _execute_clauseelement
    ret = self._execute_context(
          ^^^^^^^^^^^^^^^^^^^^^^
  File "/home/runner/workspace/.pythonlibs/lib/python3.11/site-packages/sqlalchemy/engine/base.py", line 1842, in _execute_context
    return self._exec_single_context(
           ^^^^^^^^^^^^^^^^^^^^^^^^^^
  File "/home/runner/workspace/.pythonlibs/lib/python3.11/site-packages/sqlalchemy/engine/base.py", line 1982, in _exec_single_context
    self._handle_dbapi_exception(
  File "/home/runner/workspace/.pythonlibs/lib/python3.11/site-packages/sqlalchemy/engine/base.py", line 2351, in _handle_dbapi_exception
    raise sqlalchemy_exception.with_traceback(exc_info[2]) from e
  File "/home/runner/workspace/.pythonlibs/lib/python3.11/site-packages/sqlalchemy/engine/base.py", line 1963, in _exec_single_context
    self.dialect.do_execute(
  File "/home/runner/workspace/.pythonlibs/lib/python3.11/site-packages/sqlalchemy/engine/default.py", line 943, in do_execute
    cursor.execute(statement, parameters)
sqlalchemy.exc.ProgrammingError: (psycopg2.errors.UndefinedColumn) column users.active does not exist
LINE 1: ...sers_phone, users.created_at AS users_created_at, users.acti...
                                                             ^
HINT:  Perhaps you meant to reference the column "users.is_active".

[SQL: SELECT users.id AS users_id, users.username AS users_username, users.email AS users_email, users.password_hash AS users_password_hash, users.first_name AS users_first_name, users.last_name AS users_last_name, users.phone AS users_phone, users.created_at AS users_created_at, users.active AS users_active 
FROM users 
WHERE users.id = %(pk_1)s]
[parameters: {'pk_1': 2}]
(Background on this error at: https://sqlalche.me/e/20/f405)
